Exception cancels somewhere for XMLHttpRequest for synchronouse query
User-Agent:       Mozilla/5.0 (Windows; U; Windows NT 5.1; ru; rv:1.8.1.7) Gecko/20070914 Firefox/2.0.0.7
Build Identifier: Mozilla/5.0 (Windows; U; Windows NT 5.1; ru; rv:1.8.1.7) Gecko/20070914 Firefox/2.0.0.7

If I throw exception in handler method for on readystatechange. It cancels somewhere and I can not catch it

Reproducible: Always

Steps to Reproduce:
<script type="text/javascript">
var r;
function handler() {
	 if( r.readyState == 4 ) {
	 	 alert( "Ready for excaption?" );
	 	 throw "This exception canceled any where...";
	 	 }
	 }

function main() {
	 r= new XMLHttpRequest();
  r.onreadystatechange= handler;
	 r.open( 'GET', 'test.txt', false );
	 try {
    r.send();
    alert( "Excepiton is not fired canched =(" );
    }
  catch (e) {
  	 alert( e );
  	 }
	 }

window.onload= main();
</script>
Actual Results:  
Exception cancels somewhere

Expected Results:  
Exception catched by catch block